Exception in thread Thread-1 (node_thread):
Traceback (most recent call last):
  File "/opt/homebrew/Cellar/python@3.13/3.13.5/Frameworks/Python.framework/Versions/3.13/lib/python3.13/threading.py", line 1043, in _bootstrap_inner
    self.run()
    ~~~~~~~~^^
  File "/opt/homebrew/Cellar/python@3.13/3.13.5/Frameworks/Python.framework/Versions/3.13/lib/python3.13/threading.py", line 994, in run
    self._target(*self._args, **self._kwargs)
    ~~~~~~~~~~~~^^^^^^^^^^^^^^^^^^^^^^^^^^^^^
  File "/Users/mini1/Movies/mlx_grpc_inference/.venv/lib/python3.13/site-packages/mlx/distributed_run.py", line 325, in node_thread
    c = run(cmd, check=True, shell=True, capture_output=True, text=True)
  File "/opt/homebrew/Cellar/python@3.13/3.13.5/Frameworks/Python.framework/Versions/3.13/lib/python3.13/subprocess.py", line 577, in run
    raise CalledProcessError(retcode, process.args,
                             output=stdout, stderr=stderr)
subprocess.CalledProcessError: Command 'ssh 192.168.5.2 'pid=$(cat zsh:1: no such file or directory: /Users/mini1/Movies/mlx_grpc_inference/.venv/bin/python); if ps -p $pid >/dev/null; then     kill $pid;     echo 1; else     echo 0; fi; rm zsh:1: no such file or directory: /Users/mini1/Movies/mlx_grpc_inference/.venv/bin/python'' returned non-zero exit status 1.
