[2025-08-04 11:23:59] === MLX Distributed Inference Launcher ===
[2025-08-04 11:23:59] Timestamp: 20250804_112359
[2025-08-04 11:23:59] Log directory: /Users/mini1/Movies/mlx_grpc_inference/logs
[2025-08-04 11:23:59] Cleaning up existing processes...
[2025-08-04 11:24:01] Configuring network...
[2025-08-04 11:24:01] Setting MTU to 9000 on bridge0...
[2025-08-04 11:24:01] Setting up remote files on 192.168.5.2...
[2025-08-04 11:24:02] Remote setup complete
[2025-08-04 11:24:02] Testing connectivity...
[2025-08-04 11:24:02] Testing MPI connectivity to 192.168.5.2...
[2025-08-04 11:24:02] Running MPI connectivity test...
Traceback (most recent call last):
  File "/Users/mini1/Movies/mlx_grpc_inference/test_mpi_connectivity.py", line 7, in <module>
    import mlx.core as mx
ModuleNotFoundError: No module named 'mlx'
[2025-08-04 11:24:02] âœ… MPI connectivity test passed
[2025-08-04 11:24:02] Launching with MPI backend over Thunderbolt...
[2025-08-04 11:24:02] MPI launched with PID 75921
[2025-08-04 11:24:02] Waiting for API server to start...
[mini1.local:75920] PMIX ERROR: PMIX_ERR_EXISTS in file common/pmix_iof.c at line 840
[mini1.local:75920] PMIX ERROR: PMIX_ERR_IOF_FAILURE in file iof_hnp_read.c at line 59
[mini1.local:75920] PMIX ERROR: PMIX_ERR_EXISTS in file common/pmix_iof.c at line 840
[mini1.local:75920] PMIX ERROR: PMIX_ERR_IOF_FAILURE in file iof_hnp_read.c at line 59
